[2025-02-13T18:18:04.700+0000] {local_task_job_runner.py:123} INFO - ::group::Pre task execution logs
[2025-02-13T18:18:04.733+0000] {taskinstance.py:2613} INFO - Dependencies all met for dep_context=non-requeueable deps ti=<TaskInstance: dag_for_dbt_json.Check_if_data_exists manual__2025-02-13T18:17:57+00:00 [queued]>
[2025-02-13T18:18:04.756+0000] {taskinstance.py:2613} INFO - Dependencies all met for dep_context=requeueable deps ti=<TaskInstance: dag_for_dbt_json.Check_if_data_exists manual__2025-02-13T18:17:57+00:00 [queued]>
[2025-02-13T18:18:04.758+0000] {taskinstance.py:2866} INFO - Starting attempt 1 of 1
[2025-02-13T18:18:04.792+0000] {taskinstance.py:2889} INFO - Executing <Task(BranchPythonOperator): Check_if_data_exists> on 2025-02-13 18:17:57+00:00
[2025-02-13T18:18:04.800+0000] {warnings.py:112} WARNING - /home/***/.local/lib/python3.12/site-packages/***/task/task_runner/standard_task_runner.py:70: DeprecationWarning: This process (pid=514) is multi-threaded, use of fork() may lead to deadlocks in the child.
  pid = os.fork()

[2025-02-13T18:18:04.808+0000] {standard_task_runner.py:72} INFO - Started process 515 to run task
[2025-02-13T18:18:04.807+0000] {standard_task_runner.py:104} INFO - Running: ['***', 'tasks', 'run', 'dag_for_dbt_json', 'Check_if_data_exists', 'manual__2025-02-13T18:17:57+00:00', '--job-id', '295', '--raw', '--subdir', 'DAGS_FOLDER/json_dag.py', '--cfg-path', '/tmp/tmpcvttxuju']
[2025-02-13T18:18:04.811+0000] {standard_task_runner.py:105} INFO - Job 295: Subtask Check_if_data_exists
[2025-02-13T18:18:04.898+0000] {task_command.py:467} INFO - Running <TaskInstance: dag_for_dbt_json.Check_if_data_exists manual__2025-02-13T18:17:57+00:00 [running]> on host 02531b93d66a
[2025-02-13T18:18:05.071+0000] {taskinstance.py:3132} INFO - Exporting env vars: AIRFLOW_CTX_DAG_OWNER='***' AIRFLOW_CTX_DAG_ID='dag_for_dbt_json' AIRFLOW_CTX_TASK_ID='Check_if_data_exists' AIRFLOW_CTX_EXECUTION_DATE='2025-02-13T18:17:57+00:00' AIRFLOW_CTX_TRY_NUMBER='1' AIRFLOW_CTX_DAG_RUN_ID='manual__2025-02-13T18:17:57+00:00'
[2025-02-13T18:18:05.073+0000] {taskinstance.py:731} INFO - ::endgroup::
[2025-02-13T18:18:05.112+0000] {baseoperator.py:421} WARNING - BranchPythonOperator.execute cannot be called outside TaskInstance!
[2025-02-13T18:18:06.024+0000] {python.py:240} INFO - Done. Returned value was: dbt_curl_command
[2025-02-13T18:18:06.028+0000] {branch.py:38} INFO - Branch into dbt_curl_command
[2025-02-13T18:18:06.029+0000] {skipmixin.py:230} INFO - Following branch ('dbt_curl_command',)
[2025-02-13T18:18:06.048+0000] {skipmixin.py:278} INFO - Skipping tasks [('Upload_data_to_s3', -1)]
[2025-02-13T18:18:06.106+0000] {taskinstance.py:340} INFO - ::group::Post task execution logs
[2025-02-13T18:18:06.108+0000] {taskinstance.py:352} INFO - Marking task as SUCCESS. dag_id=dag_for_dbt_json, task_id=Check_if_data_exists, run_id=manual__2025-02-13T18:17:57+00:00, execution_date=20250213T181757, start_date=20250213T181804, end_date=20250213T181806
[2025-02-13T18:18:06.152+0000] {local_task_job_runner.py:266} INFO - Task exited with return code 0
[2025-02-13T18:18:06.212+0000] {taskinstance.py:3895} INFO - 1 downstream tasks scheduled from follow-on schedule check
[2025-02-13T18:18:06.218+0000] {local_task_job_runner.py:245} INFO - ::endgroup::
