[2025-02-12T06:01:09.984+0000] {local_task_job_runner.py:123} INFO - ::group::Pre task execution logs
[2025-02-12T06:01:09.997+0000] {taskinstance.py:2613} INFO - Dependencies all met for dep_context=non-requeueable deps ti=<TaskInstance: dag_for_dbt_raw.Check_if_data_exists manual__2025-02-12T01:01:04-05:00 [queued]>
[2025-02-12T06:01:10.006+0000] {taskinstance.py:2613} INFO - Dependencies all met for dep_context=requeueable deps ti=<TaskInstance: dag_for_dbt_raw.Check_if_data_exists manual__2025-02-12T01:01:04-05:00 [queued]>
[2025-02-12T06:01:10.007+0000] {taskinstance.py:2866} INFO - Starting attempt 1 of 1
[2025-02-12T06:01:10.021+0000] {taskinstance.py:2889} INFO - Executing <Task(BranchPythonOperator): Check_if_data_exists> on 2025-02-12 06:01:04+00:00
[2025-02-12T06:01:10.027+0000] {warnings.py:112} WARNING - /home/***/.local/lib/python3.12/site-packages/***/task/task_runner/standard_task_runner.py:70: DeprecationWarning: This process (pid=1325) is multi-threaded, use of fork() may lead to deadlocks in the child.
  pid = os.fork()

[2025-02-12T06:01:10.028+0000] {standard_task_runner.py:72} INFO - Started process 1326 to run task
[2025-02-12T06:01:10.029+0000] {standard_task_runner.py:104} INFO - Running: ['***', 'tasks', 'run', 'dag_for_dbt_raw', 'Check_if_data_exists', 'manual__2025-02-12T01:01:04-05:00', '--job-id', '169', '--raw', '--subdir', 'DAGS_FOLDER/dbt_raw_dag.py', '--cfg-path', '/tmp/tmpbyc71l09']
[2025-02-12T06:01:10.030+0000] {standard_task_runner.py:105} INFO - Job 169: Subtask Check_if_data_exists
[2025-02-12T06:01:10.074+0000] {task_command.py:467} INFO - Running <TaskInstance: dag_for_dbt_raw.Check_if_data_exists manual__2025-02-12T01:01:04-05:00 [running]> on host 91e1ec71f461
[2025-02-12T06:01:10.151+0000] {taskinstance.py:3132} INFO - Exporting env vars: AIRFLOW_CTX_DAG_OWNER='***' AIRFLOW_CTX_DAG_ID='dag_for_dbt_raw' AIRFLOW_CTX_TASK_ID='Check_if_data_exists' AIRFLOW_CTX_EXECUTION_DATE='2025-02-12T06:01:04+00:00' AIRFLOW_CTX_TRY_NUMBER='1' AIRFLOW_CTX_DAG_RUN_ID='manual__2025-02-12T01:01:04-05:00'
[2025-02-12T06:01:10.153+0000] {taskinstance.py:731} INFO - ::endgroup::
[2025-02-12T06:01:10.170+0000] {baseoperator.py:421} WARNING - BranchPythonOperator.execute cannot be called outside TaskInstance!
[2025-02-12T06:01:10.553+0000] {python.py:240} INFO - Done. Returned value was: Upload_data_to_s3
[2025-02-12T06:01:10.554+0000] {branch.py:38} INFO - Branch into Upload_data_to_s3
[2025-02-12T06:01:10.555+0000] {skipmixin.py:230} INFO - Following branch ('Upload_data_to_s3',)
[2025-02-12T06:01:10.563+0000] {skipmixin.py:278} INFO - Skipping tasks [('dbt_curl_command', -1)]
[2025-02-12T06:01:10.592+0000] {taskinstance.py:340} INFO - ::group::Post task execution logs
[2025-02-12T06:01:10.593+0000] {taskinstance.py:352} INFO - Marking task as SUCCESS. dag_id=dag_for_dbt_raw, task_id=Check_if_data_exists, run_id=manual__2025-02-12T01:01:04-05:00, execution_date=20250212T060104, start_date=20250212T060109, end_date=20250212T060110
[2025-02-12T06:01:10.646+0000] {local_task_job_runner.py:266} INFO - Task exited with return code 0
[2025-02-12T06:01:10.674+0000] {taskinstance.py:3895} INFO - 1 downstream tasks scheduled from follow-on schedule check
[2025-02-12T06:01:10.678+0000] {local_task_job_runner.py:245} INFO - ::endgroup::
