[2025-02-13T04:11:56.670+0000] {local_task_job_runner.py:123} INFO - ::group::Pre task execution logs
[2025-02-13T04:11:56.740+0000] {taskinstance.py:2613} INFO - Dependencies all met for dep_context=non-requeueable deps ti=<TaskInstance: dag_for_dbt_json.Check_if_data_exists manual__2025-02-12T23:11:42-05:00 [queued]>
[2025-02-13T04:11:56.786+0000] {taskinstance.py:2613} INFO - Dependencies all met for dep_context=requeueable deps ti=<TaskInstance: dag_for_dbt_json.Check_if_data_exists manual__2025-02-12T23:11:42-05:00 [queued]>
[2025-02-13T04:11:56.787+0000] {taskinstance.py:2866} INFO - Starting attempt 1 of 1
[2025-02-13T04:11:56.948+0000] {taskinstance.py:2889} INFO - Executing <Task(BranchPythonOperator): Check_if_data_exists> on 2025-02-13 04:11:42+00:00
[2025-02-13T04:11:56.976+0000] {warnings.py:112} WARNING - /home/***/.local/lib/python3.12/site-packages/***/task/task_runner/standard_task_runner.py:70: DeprecationWarning: This process (pid=171) is multi-threaded, use of fork() may lead to deadlocks in the child.
  pid = os.fork()

[2025-02-13T04:11:56.984+0000] {standard_task_runner.py:72} INFO - Started process 172 to run task
[2025-02-13T04:11:56.983+0000] {standard_task_runner.py:104} INFO - Running: ['***', 'tasks', 'run', 'dag_for_dbt_json', 'Check_if_data_exists', 'manual__2025-02-12T23:11:42-05:00', '--job-id', '275', '--raw', '--subdir', 'DAGS_FOLDER/json_dag.py', '--cfg-path', '/tmp/tmpkn4b8b_h']
[2025-02-13T04:11:56.986+0000] {standard_task_runner.py:105} INFO - Job 275: Subtask Check_if_data_exists
[2025-02-13T04:11:57.142+0000] {task_command.py:467} INFO - Running <TaskInstance: dag_for_dbt_json.Check_if_data_exists manual__2025-02-12T23:11:42-05:00 [running]> on host 1e4529fab6d8
[2025-02-13T04:11:57.356+0000] {taskinstance.py:3132} INFO - Exporting env vars: AIRFLOW_CTX_DAG_OWNER='***' AIRFLOW_CTX_DAG_ID='dag_for_dbt_json' AIRFLOW_CTX_TASK_ID='Check_if_data_exists' AIRFLOW_CTX_EXECUTION_DATE='2025-02-13T04:11:42+00:00' AIRFLOW_CTX_TRY_NUMBER='1' AIRFLOW_CTX_DAG_RUN_ID='manual__2025-02-12T23:11:42-05:00'
[2025-02-13T04:11:57.358+0000] {taskinstance.py:731} INFO - ::endgroup::
[2025-02-13T04:11:57.481+0000] {baseoperator.py:421} WARNING - BranchPythonOperator.execute cannot be called outside TaskInstance!
[2025-02-13T04:11:59.137+0000] {python.py:240} INFO - Done. Returned value was: Upload_data_to_s3
[2025-02-13T04:11:59.142+0000] {branch.py:38} INFO - Branch into Upload_data_to_s3
[2025-02-13T04:11:59.160+0000] {skipmixin.py:230} INFO - Following branch ('Upload_data_to_s3',)
[2025-02-13T04:11:59.173+0000] {skipmixin.py:278} INFO - Skipping tasks []
[2025-02-13T04:11:59.221+0000] {taskinstance.py:340} INFO - ::group::Post task execution logs
[2025-02-13T04:11:59.222+0000] {taskinstance.py:352} INFO - Marking task as SUCCESS. dag_id=dag_for_dbt_json, task_id=Check_if_data_exists, run_id=manual__2025-02-12T23:11:42-05:00, execution_date=20250213T041142, start_date=20250213T041156, end_date=20250213T041159
[2025-02-13T04:11:59.286+0000] {local_task_job_runner.py:266} INFO - Task exited with return code 0
[2025-02-13T04:11:59.339+0000] {taskinstance.py:3895} INFO - 1 downstream tasks scheduled from follow-on schedule check
[2025-02-13T04:11:59.343+0000] {local_task_job_runner.py:245} INFO - ::endgroup::
