[2025-02-11T02:22:23.059+0000] {local_task_job_runner.py:123} INFO - ::group::Pre task execution logs
[2025-02-11T02:22:23.076+0000] {taskinstance.py:2613} INFO - Dependencies all met for dep_context=non-requeueable deps ti=<TaskInstance: dag_to_scrape_and_upload.test_dbt_curl manual__2025-02-11T02:22:21.676955+00:00 [queued]>
[2025-02-11T02:22:23.086+0000] {taskinstance.py:2613} INFO - Dependencies all met for dep_context=requeueable deps ti=<TaskInstance: dag_to_scrape_and_upload.test_dbt_curl manual__2025-02-11T02:22:21.676955+00:00 [queued]>
[2025-02-11T02:22:23.087+0000] {taskinstance.py:2866} INFO - Starting attempt 1 of 1
[2025-02-11T02:22:23.105+0000] {taskinstance.py:2889} INFO - Executing <Task(BashOperator): test_dbt_curl> on 2025-02-11 02:22:21.676955+00:00
[2025-02-11T02:22:23.112+0000] {warnings.py:112} WARNING - /home/***/.local/lib/python3.12/site-packages/***/task/task_runner/standard_task_runner.py:70: DeprecationWarning: This process (pid=1086) is multi-threaded, use of fork() may lead to deadlocks in the child.
  pid = os.fork()

[2025-02-11T02:22:23.116+0000] {standard_task_runner.py:72} INFO - Started process 1087 to run task
[2025-02-11T02:22:23.116+0000] {standard_task_runner.py:104} INFO - Running: ['***', 'tasks', 'run', 'dag_to_scrape_and_upload', 'test_dbt_curl', 'manual__2025-02-11T02:22:21.676955+00:00', '--job-id', '98', '--raw', '--subdir', 'DAGS_FOLDER/scrape_upload_dag.py', '--cfg-path', '/tmp/tmp6tj3n7l5']
[2025-02-11T02:22:23.117+0000] {standard_task_runner.py:105} INFO - Job 98: Subtask test_dbt_curl
[2025-02-11T02:22:23.175+0000] {task_command.py:467} INFO - Running <TaskInstance: dag_to_scrape_and_upload.test_dbt_curl manual__2025-02-11T02:22:21.676955+00:00 [running]> on host ecdf8258250e
[2025-02-11T02:22:23.280+0000] {taskinstance.py:3132} INFO - Exporting env vars: AIRFLOW_CTX_DAG_OWNER='***' AIRFLOW_CTX_DAG_ID='dag_to_scrape_and_upload' AIRFLOW_CTX_TASK_ID='test_dbt_curl' AIRFLOW_CTX_EXECUTION_DATE='2025-02-11T02:22:21.676955+00:00' AIRFLOW_CTX_TRY_NUMBER='1' AIRFLOW_CTX_DAG_RUN_ID='manual__2025-02-11T02:22:21.676955+00:00'
[2025-02-11T02:22:23.282+0000] {taskinstance.py:731} INFO - ::endgroup::
[2025-02-11T02:22:23.298+0000] {subprocess.py:78} INFO - Tmp dir root location: /tmp
[2025-02-11T02:22:23.299+0000] {subprocess.py:88} INFO - Running command: ['/usr/bin/bash', '-c', ' curl -X POST "https://bn544.us1.dbt.com/api/v2/accounts/70471823424708/jobs/70471823425377/run/" \\ -H "Authorization: Token dbtu_aSKjCT4DBp7NVMX7ZIOj9Meosndn7W8Y2pD3K--X3a-v_pArxA" \\ -H "Content-Type: application/json" \\ -d \'{ \\   "cause": "Triggered via API", \\   "steps_override": ["dbt run --select raw.sub --vars \\"{\\\\"year\\\\":\\\\"2024\\\\", \\\\\\"qtr\\\\": \\\\\\"4\\\\"}\\""] \\ }\' ']
[2025-02-11T02:22:23.312+0000] {subprocess.py:99} INFO - Output:
[2025-02-11T02:22:23.324+0000] {subprocess.py:106} INFO -   % Total    % Received % Xferd  Average Speed   Time    Time     Time  Current
[2025-02-11T02:22:23.324+0000] {subprocess.py:106} INFO -                                  Dload  Upload   Total   Spent    Left  Speed
[2025-02-11T02:22:23.510+0000] {subprocess.py:106} INFO -   0     0    0     0    0     0      0      0 --:--:-- --:--:-- --:--:--     0  0     0    0     0    0     0      0      0 --:--:-- --:--:-- --:--:--     0100    58  100    58    0     0    311      0 --:--:-- --:--:-- --:--:--   310
[2025-02-11T02:22:23.511+0000] {subprocess.py:106} INFO - {"detail":"Authentication credentials were not provided."}curl: (3) URL using bad/illegal format or missing URL
[2025-02-11T02:22:23.512+0000] {subprocess.py:106} INFO - curl: (3) URL using bad/illegal format or missing URL
[2025-02-11T02:22:23.514+0000] {subprocess.py:106} INFO - curl: (3) URL using bad/illegal format or missing URL
[2025-02-11T02:22:23.514+0000] {subprocess.py:106} INFO - curl: (3) URL using bad/illegal format or missing URL
[2025-02-11T02:22:23.516+0000] {subprocess.py:106} INFO - curl: (3) URL using bad/illegal format or missing URL
[2025-02-11T02:22:23.516+0000] {subprocess.py:106} INFO - curl: (3) nested brace in URL position 59:
[2025-02-11T02:22:23.518+0000] {subprocess.py:106} INFO - { \   "cause": "Triggered via API", \   "steps_override": ["dbt run --select raw.sub --vars \"{\\"year\\":\\"2024\\", \\\"qtr\\": \\\"4\\"}\""] \ }
[2025-02-11T02:22:23.519+0000] {subprocess.py:106} INFO -                                                           ^
[2025-02-11T02:22:23.520+0000] {subprocess.py:110} INFO - Command exited with return code 3
[2025-02-11T02:22:23.539+0000] {taskinstance.py:3311} ERROR - Task failed with exception
Traceback (most recent call last):
  File "/home/airflow/.local/lib/python3.12/site-packages/airflow/models/taskinstance.py", line 767, in _execute_task
    result = _execute_callable(context=context, **execute_callable_kwargs)
             ^^^^^^^^^^^^^^^^^^^^^^^^^^^^^^^^^^^^^^^^^^^^^^^^^^^^^^^^^^^^^
  File "/home/airflow/.local/lib/python3.12/site-packages/airflow/models/taskinstance.py", line 733, in _execute_callable
    return ExecutionCallableRunner(
           ^^^^^^^^^^^^^^^^^^^^^^^^
  File "/home/airflow/.local/lib/python3.12/site-packages/airflow/utils/operator_helpers.py", line 252, in run
    return self.func(*args, **kwargs)
           ^^^^^^^^^^^^^^^^^^^^^^^^^^
  File "/home/airflow/.local/lib/python3.12/site-packages/airflow/models/baseoperator.py", line 422, in wrapper
    return func(self, *args, **kwargs)
           ^^^^^^^^^^^^^^^^^^^^^^^^^^^
  File "/home/airflow/.local/lib/python3.12/site-packages/airflow/operators/bash.py", line 276, in execute
    raise AirflowException(
airflow.exceptions.AirflowException: Bash command failed. The command returned a non-zero exit code 3.
[2025-02-11T02:22:23.547+0000] {taskinstance.py:1225} INFO - Marking task as FAILED. dag_id=dag_to_scrape_and_upload, task_id=test_dbt_curl, run_id=manual__2025-02-11T02:22:21.676955+00:00, execution_date=20250211T022221, start_date=20250211T022223, end_date=20250211T022223
[2025-02-11T02:22:23.566+0000] {taskinstance.py:340} INFO - ::group::Post task execution logs
[2025-02-11T02:22:23.568+0000] {standard_task_runner.py:124} ERROR - Failed to execute job 98 for task test_dbt_curl (Bash command failed. The command returned a non-zero exit code 3.; 1087)
Traceback (most recent call last):
  File "/home/airflow/.local/lib/python3.12/site-packages/airflow/task/task_runner/standard_task_runner.py", line 117, in _start_by_fork
    ret = args.func(args, dag=self.dag)
          ^^^^^^^^^^^^^^^^^^^^^^^^^^^^^
  File "/home/airflow/.local/lib/python3.12/site-packages/airflow/cli/cli_config.py", line 49, in command
    return func(*args, **kwargs)
           ^^^^^^^^^^^^^^^^^^^^^
  File "/home/airflow/.local/lib/python3.12/site-packages/airflow/utils/cli.py", line 116, in wrapper
    return f(*args, **kwargs)
           ^^^^^^^^^^^^^^^^^^
  File "/home/airflow/.local/lib/python3.12/site-packages/airflow/cli/commands/task_command.py", line 483, in task_run
    task_return_code = _run_task_by_selected_method(args, _dag, ti)
                       ^^^^^^^^^^^^^^^^^^^^^^^^^^^^^^^^^^^^^^^^^^^^
  File "/home/airflow/.local/lib/python3.12/site-packages/airflow/cli/commands/task_command.py", line 256, in _run_task_by_selected_method
    return _run_raw_task(args, ti)
           ^^^^^^^^^^^^^^^^^^^^^^^
  File "/home/airflow/.local/lib/python3.12/site-packages/airflow/cli/commands/task_command.py", line 341, in _run_raw_task
    return ti._run_raw_task(
           ^^^^^^^^^^^^^^^^^
  File "/home/airflow/.local/lib/python3.12/site-packages/airflow/utils/session.py", line 97, in wrapper
    return func(*args, session=session, **kwargs)
           ^^^^^^^^^^^^^^^^^^^^^^^^^^^^^^^^^^^^^^
  File "/home/airflow/.local/lib/python3.12/site-packages/airflow/models/taskinstance.py", line 3005, in _run_raw_task
    return _run_raw_task(
           ^^^^^^^^^^^^^^
  File "/home/airflow/.local/lib/python3.12/site-packages/airflow/models/taskinstance.py", line 273, in _run_raw_task
    TaskInstance._execute_task_with_callbacks(
  File "/home/airflow/.local/lib/python3.12/site-packages/airflow/models/taskinstance.py", line 3159, in _execute_task_with_callbacks
    result = self._execute_task(context, task_orig)
             ^^^^^^^^^^^^^^^^^^^^^^^^^^^^^^^^^^^^^^
  File "/home/airflow/.local/lib/python3.12/site-packages/airflow/models/taskinstance.py", line 3183, in _execute_task
    return _execute_task(self, context, task_orig)
           ^^^^^^^^^^^^^^^^^^^^^^^^^^^^^^^^^^^^^^^
  File "/home/airflow/.local/lib/python3.12/site-packages/airflow/models/taskinstance.py", line 767, in _execute_task
    result = _execute_callable(context=context, **execute_callable_kwargs)
             ^^^^^^^^^^^^^^^^^^^^^^^^^^^^^^^^^^^^^^^^^^^^^^^^^^^^^^^^^^^^^
  File "/home/airflow/.local/lib/python3.12/site-packages/airflow/models/taskinstance.py", line 733, in _execute_callable
    return ExecutionCallableRunner(
           ^^^^^^^^^^^^^^^^^^^^^^^^
  File "/home/airflow/.local/lib/python3.12/site-packages/airflow/utils/operator_helpers.py", line 252, in run
    return self.func(*args, **kwargs)
           ^^^^^^^^^^^^^^^^^^^^^^^^^^
  File "/home/airflow/.local/lib/python3.12/site-packages/airflow/models/baseoperator.py", line 422, in wrapper
    return func(self, *args, **kwargs)
           ^^^^^^^^^^^^^^^^^^^^^^^^^^^
  File "/home/airflow/.local/lib/python3.12/site-packages/airflow/operators/bash.py", line 276, in execute
    raise AirflowException(
airflow.exceptions.AirflowException: Bash command failed. The command returned a non-zero exit code 3.
[2025-02-11T02:22:23.615+0000] {local_task_job_runner.py:266} INFO - Task exited with return code 1
[2025-02-11T02:22:23.640+0000] {taskinstance.py:3895} INFO - 0 downstream tasks scheduled from follow-on schedule check
[2025-02-11T02:22:23.643+0000] {local_task_job_runner.py:245} INFO - ::endgroup::
