[2025-02-11T19:57:09.105+0000] {local_task_job_runner.py:123} INFO - ::group::Pre task execution logs
[2025-02-11T19:57:09.157+0000] {taskinstance.py:2613} INFO - Dependencies all met for dep_context=non-requeueable deps ti=<TaskInstance: dag_to_scrape_and_upload.Upload_data_to_s3 manual__2025-02-11T14:56:34-05:00 [queued]>
[2025-02-11T19:57:09.177+0000] {taskinstance.py:2613} INFO - Dependencies all met for dep_context=requeueable deps ti=<TaskInstance: dag_to_scrape_and_upload.Upload_data_to_s3 manual__2025-02-11T14:56:34-05:00 [queued]>
[2025-02-11T19:57:09.178+0000] {taskinstance.py:2866} INFO - Starting attempt 1 of 1
[2025-02-11T19:57:09.203+0000] {taskinstance.py:2889} INFO - Executing <Task(PythonOperator): Upload_data_to_s3> on 2025-02-11 19:56:34+00:00
[2025-02-11T19:57:09.214+0000] {warnings.py:112} WARNING - /home/***/.local/lib/python3.12/site-packages/***/task/task_runner/standard_task_runner.py:70: DeprecationWarning: This process (pid=3130) is multi-threaded, use of fork() may lead to deadlocks in the child.
  pid = os.fork()

[2025-02-11T19:57:09.219+0000] {standard_task_runner.py:72} INFO - Started process 3143 to run task
[2025-02-11T19:57:09.219+0000] {standard_task_runner.py:104} INFO - Running: ['***', 'tasks', 'run', 'dag_to_scrape_and_upload', 'Upload_data_to_s3', 'manual__2025-02-11T14:56:34-05:00', '--job-id', '125', '--raw', '--subdir', 'DAGS_FOLDER/scrape_upload_dag.py', '--cfg-path', '/tmp/tmpn_ku42u8']
[2025-02-11T19:57:09.221+0000] {standard_task_runner.py:105} INFO - Job 125: Subtask Upload_data_to_s3
[2025-02-11T19:57:09.324+0000] {task_command.py:467} INFO - Running <TaskInstance: dag_to_scrape_and_upload.Upload_data_to_s3 manual__2025-02-11T14:56:34-05:00 [running]> on host ecdf8258250e
[2025-02-11T19:57:09.537+0000] {taskinstance.py:3132} INFO - Exporting env vars: AIRFLOW_CTX_DAG_OWNER='***' AIRFLOW_CTX_DAG_ID='dag_to_scrape_and_upload' AIRFLOW_CTX_TASK_ID='Upload_data_to_s3' AIRFLOW_CTX_EXECUTION_DATE='2025-02-11T19:56:34+00:00' AIRFLOW_CTX_TRY_NUMBER='1' AIRFLOW_CTX_DAG_RUN_ID='manual__2025-02-11T14:56:34-05:00'
[2025-02-11T19:57:09.553+0000] {taskinstance.py:731} INFO - ::endgroup::
[2025-02-11T19:57:30.403+0000] {logging_mixin.py:190} INFO - {'error': 'HTTPSConnectionPool(host=\'www.sec.gov\', port=443): Max retries exceeded with url: /files/dera/data/financial-statement-data-sets/2022q1.zip (Caused by NameResolutionError("<urllib3.connection.HTTPSConnection object at 0x7ff7d0877980>: Failed to resolve \'www.sec.gov\' ([Errno -3] Temporary failure in name resolution)"))'}
[2025-02-11T19:57:31.483+0000] {python.py:240} INFO - Done. Returned value was: None
[2025-02-11T19:58:01.153+0000] {job.py:229} INFO - Heartbeat recovered after 42.36 seconds
[2025-02-11T19:58:01.155+0000] {taskinstance.py:340} INFO - ::group::Post task execution logs
[2025-02-11T19:58:01.157+0000] {taskinstance.py:352} INFO - Marking task as SUCCESS. dag_id=dag_to_scrape_and_upload, task_id=Upload_data_to_s3, run_id=manual__2025-02-11T14:56:34-05:00, execution_date=20250211T195634, start_date=20250211T195709, end_date=20250211T195801
[2025-02-11T19:58:01.291+0000] {local_task_job_runner.py:266} INFO - Task exited with return code 0
[2025-02-11T19:58:01.337+0000] {taskinstance.py:3895} INFO - 0 downstream tasks scheduled from follow-on schedule check
[2025-02-11T19:58:01.364+0000] {local_task_job_runner.py:245} INFO - ::endgroup::
