[2025-02-13T03:45:10.486+0000] {local_task_job_runner.py:123} INFO - ::group::Pre task execution logs
[2025-02-13T03:45:10.516+0000] {taskinstance.py:2613} INFO - Dependencies all met for dep_context=non-requeueable deps ti=<TaskInstance: dag_for_dbt_json.Check_if_data_exists manual__2025-02-12T22:44:51-05:00 [queued]>
[2025-02-13T03:45:10.529+0000] {taskinstance.py:2613} INFO - Dependencies all met for dep_context=requeueable deps ti=<TaskInstance: dag_for_dbt_json.Check_if_data_exists manual__2025-02-12T22:44:51-05:00 [queued]>
[2025-02-13T03:45:10.530+0000] {taskinstance.py:2866} INFO - Starting attempt 1 of 1
[2025-02-13T03:45:10.547+0000] {taskinstance.py:2889} INFO - Executing <Task(BranchPythonOperator): Check_if_data_exists> on 2025-02-13 03:44:51+00:00
[2025-02-13T03:45:10.555+0000] {warnings.py:112} WARNING - /home/***/.local/lib/python3.12/site-packages/***/task/task_runner/standard_task_runner.py:70: DeprecationWarning: This process (pid=1882) is multi-threaded, use of fork() may lead to deadlocks in the child.
  pid = os.fork()

[2025-02-13T03:45:10.557+0000] {standard_task_runner.py:104} INFO - Running: ['***', 'tasks', 'run', 'dag_for_dbt_json', 'Check_if_data_exists', 'manual__2025-02-12T22:44:51-05:00', '--job-id', '263', '--raw', '--subdir', 'DAGS_FOLDER/json_dag.py', '--cfg-path', '/tmp/tmpljdndh_c']
[2025-02-13T03:45:10.560+0000] {standard_task_runner.py:72} INFO - Started process 1883 to run task
[2025-02-13T03:45:10.561+0000] {standard_task_runner.py:105} INFO - Job 263: Subtask Check_if_data_exists
[2025-02-13T03:45:10.604+0000] {task_command.py:467} INFO - Running <TaskInstance: dag_for_dbt_json.Check_if_data_exists manual__2025-02-12T22:44:51-05:00 [running]> on host f917fd63a571
[2025-02-13T03:45:10.708+0000] {taskinstance.py:3132} INFO - Exporting env vars: AIRFLOW_CTX_DAG_OWNER='***' AIRFLOW_CTX_DAG_ID='dag_for_dbt_json' AIRFLOW_CTX_TASK_ID='Check_if_data_exists' AIRFLOW_CTX_EXECUTION_DATE='2025-02-13T03:44:51+00:00' AIRFLOW_CTX_TRY_NUMBER='1' AIRFLOW_CTX_DAG_RUN_ID='manual__2025-02-12T22:44:51-05:00'
[2025-02-13T03:45:10.710+0000] {taskinstance.py:731} INFO - ::endgroup::
[2025-02-13T03:45:10.739+0000] {baseoperator.py:421} WARNING - BranchPythonOperator.execute cannot be called outside TaskInstance!
[2025-02-13T03:45:11.494+0000] {python.py:240} INFO - Done. Returned value was: Upload_data_to_s3
[2025-02-13T03:45:11.497+0000] {branch.py:38} INFO - Branch into Upload_data_to_s3
[2025-02-13T03:45:11.498+0000] {skipmixin.py:230} INFO - Following branch ('Upload_data_to_s3',)
[2025-02-13T03:45:11.506+0000] {skipmixin.py:278} INFO - Skipping tasks []
[2025-02-13T03:45:11.528+0000] {taskinstance.py:340} INFO - ::group::Post task execution logs
[2025-02-13T03:45:11.530+0000] {taskinstance.py:352} INFO - Marking task as SUCCESS. dag_id=dag_for_dbt_json, task_id=Check_if_data_exists, run_id=manual__2025-02-12T22:44:51-05:00, execution_date=20250213T034451, start_date=20250213T034510, end_date=20250213T034511
[2025-02-13T03:45:11.591+0000] {local_task_job_runner.py:266} INFO - Task exited with return code 0
[2025-02-13T03:45:11.638+0000] {taskinstance.py:3895} INFO - 2 downstream tasks scheduled from follow-on schedule check
[2025-02-13T03:45:11.641+0000] {local_task_job_runner.py:245} INFO - ::endgroup::
